Workbook
Name HomeEdge: 'NHL Model'!$B$1

Sheet NHL2025-26Results
A1: Date | B1: Visitor | C1: G | D1: Home | E1: G_1 | F1: Column1 | G1: Winning Team | H1: Losing Team | I1: Winning_G | J1: Losing_G
A2: 2025-10-07 | B2: Chicago Blackhawks | C2: 2 | D2: Florida Panthers | E2: 3 | G2: Florida Panthers | H2: Chicago Blackhawks | I2: 3 | J2: 2
A3: 2025-10-07 | B3: Colorado Avalanche | C3: 4 | D3: Los Angeles Kings | E3: 1 | G3: Colorado Avalanche | H3: Los Angeles Kings | I3: 4 | J3: 1
A4: 2025-10-07 | B4: Pittsburgh Penguins | C4: 3 | D4: New York Rangers | E4: 0 | G4: Pittsburgh Penguins | H4: New York Rangers | I4: 3 | J4: 0
A5: 2025-10-08 | B5: Calgary Flames | C5: 4 | D5: Edmonton Oilers | E5: 3 | F5: SO | G5: Calgary Flames | H5: Edmonton Oilers | I5: 4 | J5: 3
A6: 2025-10-08 | B6: Montreal Canadiens | C6: 2 | D6: Toronto Maple Leafs | E6: 5 | G6: Toronto Maple Leafs | H6: Montreal Canadiens | I6: 5 | J6: 2
A7: 2025-10-08 | B7: Los Angeles Kings | C7: 6 | D7: Vegas Golden Knights | E7: 5 | F7: SO | G7: Los Angeles Kings | H7: Vegas Golden Knights | I7: 6 | J7: 5
A8: 2025-10-08 | B8: Boston Bruins | C8: 3 | D8: Washington Capitals | E8: 1 | G8: Boston Bruins | H8: Washington Capitals | I8: 3 | J8: 1
A9: 2025-10-09 | B9: Chicago Blackhawks | C9: 3 | D9: Boston Bruins | E9: 4 | F9: OT | G9: Boston Bruins | H9: Chicago Blackhawks | I9: 4 | J9: 3
A10: 2025-10-09 | B10: New York Rangers | C10: 4 | D10: Buffalo Sabres | E10: 0 | G10: New York Rangers | H10: Buffalo Sabres | I10: 4 | J10: 0
A11: 2025-10-09 | B11: New Jersey Devils | C11: 3 | D11: Carolina Hurricanes | E11: 6 | G11: Carolina Hurricanes | H11: New Jersey Devils | I11: 6 | J11: 3
A12: 2025-10-09 | B12: Utah Mammoth | C12: 1 | D12: Colorado Avalanche | E12: 2 | G12: Colorado Avalanche | H12: Utah Mammoth | I12: 2 | J12: 1
A13: 2025-10-09 | B13: Montreal Canadiens | C13: 5 | D13: Detroit Red Wings | E13: 1 | G13: Montreal Canadiens | H13: Detroit Red Wings | I13: 5 | J13: 1
A14: 2025-10-09 | B14: Philadelphia Flyers | C14: 1 | D14: Florida Panthers | E14: 2 | G14: Florida Panthers | H14: Philadelphia Flyers | I14: 2 | J14: 1
A15: 2025-10-09 | B15: Columbus Blue Jackets | C15: 1 | D15: Nashville Predators | E15: 2 | G15: Nashville Predators | H15: Columbus Blue Jackets | I15: 2 | J15: 1
A16: 2025-10-09 | B16: New York Islanders | C16: 3 | D16: Pittsburgh Penguins | E16: 4 | G16: Pittsburgh Penguins | H16: New York Islanders | I16: 4 | J16: 3
A17: 2025-10-09 | B17: Anaheim Ducks | C17: 1 | D17: Seattle Kraken | E17: 3 | G17: Seattle Kraken | H17: Anaheim Ducks | I17: 3 | J17: 1
A18: 2025-10-09 | B18: Vegas Golden Knights | C18: 4 | D18: San Jose Sharks | E18: 3 | F18: OT | G18: Vegas Golden Knights | H18: San Jose Sharks | I18: 4 | J18: 3
A19: 2025-10-09 | B19: Minnesota Wild | C19: 5 | D19: St. Louis Blues | E19: 0 | G19: Minnesota Wild | H19: St. Louis Blues | I19: 5 | J19: 0
A20: 2025-10-09 | B20: Ottawa Senators | C20: 5 | D20: Tampa Bay Lightning | E20: 4 | G20: Ottawa Senators | H20: Tampa Bay Lightning | I20: 5 | J20: 4
A21: 2025-10-09 | B21: Calgary Flames | C21: 1 | D21: Vancouver Canucks | E21: 5 | G21: Vancouver Canucks | H21: Calgary Flames | I21: 5 | J21: 1
A22: 2025-10-09 | B22: Dallas Stars | C22: 5 | D22: Winnipeg Jets | E22: 4 | G22: Dallas Stars | H22: Winnipeg Jets | I22: 5 | J22: 4
A23: 2025-10-11 | B23: Buffalo Sabres | C23: 1 | D23: Boston Bruins | E23: 3 | G23: Boston Bruins | H23: Buffalo Sabres | I23: 3 | J23: 1
A24: 2025-10-11 | B24: Philadelphia Flyers | C24: 3 | D24: Carolina Hurricanes | E24: 4 | F24: OT | G24: Carolina Hurricanes | H24: Philadelphia Flyers | I24: 4 | J24: 3
A25: 2025-10-11 | B25: St. Louis Blues | C25: 4 | D25: Calgary Flames | E25: 2 | G25: St. Louis Blues | H25: Calgary Flames | I25: 4 | J25: 2
A26: 2025-10-11 | B26: Montreal Canadiens | C26: 3 | D26: Chicago Blackhawks | E26: 2 | G26: Montreal Canadiens | H26: Chicago Blackhawks | I26: 3 | J26: 2
A27: 2025-10-11 | B27: Dallas Stars | C27: 5 | D27: Colorado Avalanche | E27: 4 | F27: SO | G27: Dallas Stars | H27: Colorado Avalanche | I27: 5 | J27: 4
A28: 2025-10-11 | B28: Toronto Maple Leafs | C28: 3 | D28: Detroit Red Wings | E28: 6 | G28: Detroit Red Wings | H28: Toronto Maple Leafs | I28: 6 | J28: 3
A29: 2025-10-11 | B29: Vancouver Canucks | C29: 1 | D29: Edmonton Oilers | E29: 3 | G29: Edmonton Oilers | H29: Vancouver Canucks | I29: 3 | J29: 1
A30: 2025-10-11 | B30: Ottawa Senators | C30: 2 | D30: Florida Panthers | E30: 6 | G30: Florida Panthers | H30: Ottawa Senators | I30: 6 | J30: 2
A31: 2025-10-11 | B31: Columbus Blue Jackets | C31: 7 | D31: Minnesota Wild | E31: 4 | G31: Columbus Blue Jackets | H31: Minnesota Wild | I31: 7 | J31: 4
A32: 2025-10-11 | B32: Utah Mammoth | C32: 3 | D32: Nashville Predators | E32: 2 | F32: OT | G32: Utah Mammoth | H32: Nashville Predators | I32: 3 | J32: 2
A33: 2025-10-11 | B33: Washington Capitals | C33: 4 | D33: New York Islanders | E33: 2 | G33: Washington Capitals | H33: New York Islanders | I33: 4 | J33: 2
A34: 2025-10-11 | B34: New York Rangers | C34: 6 | D34: Pittsburgh Penguins | E34: 1 | G34: New York Rangers | H34: Pittsburgh Penguins | I34: 6 | J34: 1
A35: 2025-10-11 | B35: Vegas Golden Knights | C35: 1 | D35: Seattle Kraken | E35: 2 | F35: OT | G35: Seattle Kraken | H35: Vegas Golden Knights | I35: 2 | J35: 1
A36: 2025-10-11 | B36: Anaheim Ducks | C36: 7 | D36: San Jose Sharks | E36: 6 | F36: OT | G36: Anaheim Ducks | H36: San Jose Sharks | I36: 7 | J36: 6
A37: 2025-10-11 | B37: New Jersey Devils | C37: 5 | D37: Tampa Bay Lightning | E37: 3 | G37: New Jersey Devils | H37: Tampa Bay Lightning | I37: 5 | J37: 3
A38: 2025-10-11 | B38: Los Angeles Kings | C38: 2 | D38: Winnipeg Jets | E38: 3 | G38: Winnipeg Jets | H38: Los Angeles Kings | I38: 3 | J38: 2
A39: 2025-10-12 | B39: Washington Capitals | C39: 1 | D39: New York Rangers | E39: 0 | G39: Washington Capitals | H39: New York Rangers | I39: 1 | J39: 0
A40: 2025-10-13 | B40: Tampa Bay Lightning | C40: 4 | D40: Boston Bruins | E40: 3 | G40: Tampa Bay Lightning | H40: Boston Bruins | I40: 4 | J40: 3
...

Sheet NHL Model
A1: HomeEdge | B1: 0.12960699
J2: SSE
B3: 0 | J3: =SUM(Table3[Squared Difference]) -> 5481.6372
D5: Visitor | E5: G | F5: Home | G5: G_1 | H5: HomeMargin | I5: HomeForecast | J5: Squared Difference
A6: Teams | B6: Rating | D6: Chicago Blackhawks | E6: ='NHL2025-26Results'!C2 -> 2 | F6: Florida Panthers | G6: ='NHL2025-26Results'!E2 -> 3 | H6: =Table3[[#This Row],[G_1]]-Table3[[#This Row],[G]] -> 1 | I6: =HomeEdge+VLOOKUP(Table3[[#This Row],[Home]],$A$6:$B$38,2,FALSE)-VLOOKUP(Table3[[#This Row],[Visitor]],$A$6:$B$38,2,FALSE) -> 0.49923564 | J6: =(Table3[[#This Row],[HomeMargin]]-Table3[[#This Row],[HomeForecast]])^2 -> 0.25076495
A7: Anaheim Ducks | B7: -0.46360583 | D7: Colorado Avalanche | E7: ='NHL2025-26Results'!C3 -> 4 | F7: Los Angeles Kings | G7: ='NHL2025-26Results'!E3 -> 1 | H7: =Table3[[#This Row],[G_1]]-Table3[[#This Row],[G]] -> -3 | I7: =HomeEdge+VLOOKUP(Table3[[#This Row],[Home]],$A$6:$B$38,2,FALSE)-VLOOKUP(Table3[[#This Row],[Visitor]],$A$6:$B$38,2,FALSE) -> -1.4597567 | J7: =(Table3[[#This Row],[HomeMargin]]-Table3[[#This Row],[HomeForecast]])^2 -> 2.3723493
A8: Boston Bruins | B8: -0.10253061 | D8: Pittsburgh Penguins | E8: ='NHL2025-26Results'!C4 -> 3 | F8: New York Rangers | G8: ='NHL2025-26Results'!E4 -> 0 | H8: =Table3[[#This Row],[G_1]]-Table3[[#This Row],[G]] -> -3 | I8: =HomeEdge+VLOOKUP(Table3[[#This Row],[Home]],$A$6:$B$38,2,FALSE)-VLOOKUP(Table3[[#This Row],[Visitor]],$A$6:$B$38,2,FALSE) -> -0.60694852 | J8: =(Table3[[#This Row],[HomeMargin]]-Table3[[#This Row],[HomeForecast]])^2 -> 5.7266954
A9: Buffalo Sabres | B9: 0.0081543966 | D9: Calgary Flames | E9: ='NHL2025-26Results'!C5 -> 4 | F9: Edmonton Oilers | G9: ='NHL2025-26Results'!E5 -> 3 | H9: =Table3[[#This Row],[G_1]]-Table3[[#This Row],[G]] -> -1 | I9: =HomeEdge+VLOOKUP(Table3[[#This Row],[Home]],$A$6:$B$38,2,FALSE)-VLOOKUP(Table3[[#This Row],[Visitor]],$A$6:$B$38,2,FALSE) -> 0.65529325 | J9: =(Table3[[#This Row],[HomeMargin]]-Table3[[#This Row],[HomeForecast]])^2 -> 2.7399958
A10: Calgary Flames | B10: -0.89031222 | D10: Montreal Canadiens | E10: ='NHL2025-26Results'!C6 -> 2 | F10: Toronto Maple Leafs | G10: ='NHL2025-26Results'!E6 -> 5 | H10: =Table3[[#This Row],[G_1]]-Table3[[#This Row],[G]] -> 3 | I10: =HomeEdge+VLOOKUP(Table3[[#This Row],[Home]],$A$6:$B$38,2,FALSE)-VLOOKUP(Table3[[#This Row],[Visitor]],$A$6:$B$38,2,FALSE) -> -0.22639891 | J10: =(Table3[[#This Row],[HomeMargin]]-Table3[[#This Row],[HomeForecast]])^2 -> 10.40965
A11: Carolina Hurricanes | B11: 0.2324942 | D11: Los Angeles Kings | E11: ='NHL2025-26Results'!C7 -> 6 | F11: Vegas Golden Knights | G11: ='NHL2025-26Results'!E7 -> 5 | H11: =Table3[[#This Row],[G_1]]-Table3[[#This Row],[G]] -> -1 | I11: =HomeEdge+VLOOKUP(Table3[[#This Row],[Home]],$A$6:$B$38,2,FALSE)-VLOOKUP(Table3[[#This Row],[Visitor]],$A$6:$B$38,2,FALSE) -> 0.55733925 | J11: =(Table3[[#This Row],[HomeMargin]]-Table3[[#This Row],[HomeForecast]])^2 -> 2.4253055
A12: Chicago Blackhawks | B12: -0.92658078 | D12: Boston Bruins | E12: ='NHL2025-26Results'!C8 -> 3 | F12: Washington Capitals | G12: ='NHL2025-26Results'!E8 -> 1 | H12: =Table3[[#This Row],[G_1]]-Table3[[#This Row],[G]] -> -2 | I12: =HomeEdge+VLOOKUP(Table3[[#This Row],[Home]],$A$6:$B$38,2,FALSE)-VLOOKUP(Table3[[#This Row],[Visitor]],$A$6:$B$38,2,FALSE) -> 0.11236167 | J12: =(Table3[[#This Row],[HomeMargin]]-Table3[[#This Row],[HomeForecast]])^2 -> 4.4620718
A13: Colorado Avalanche | B13: 0.99866683 | D13: Chicago Blackhawks | E13: ='NHL2025-26Results'!C9 -> 3 | F13: Boston Bruins | G13: ='NHL2025-26Results'!E9 -> 4 | H13: =Table3[[#This Row],[G_1]]-Table3[[#This Row],[G]] -> 1 | I13: =HomeEdge+VLOOKUP(Table3[[#This Row],[Home]],$A$6:$B$38,2,FALSE)-VLOOKUP(Table3[[#This Row],[Visitor]],$A$6:$B$38,2,FALSE) -> 0.95365715 | J13: =(Table3[[#This Row],[HomeMargin]]-Table3[[#This Row],[HomeForecast]])^2 -> 0.0021476594
A14: Columbus Blue Jackets | B14: -0.2815648 | D14: New York Rangers | E14: ='NHL2025-26Results'!C10 -> 4 | F14: Buffalo Sabres | G14: ='NHL2025-26Results'!E10 -> 0 | H14: =Table3[[#This Row],[G_1]]-Table3[[#This Row],[G]] -> -4 | I14: =HomeEdge+VLOOKUP(Table3[[#This Row],[Home]],$A$6:$B$38,2,FALSE)-VLOOKUP(Table3[[#This Row],[Visitor]],$A$6:$B$38,2,FALSE) -> 0.87428054 | J14: =(Table3[[#This Row],[HomeMargin]]-Table3[[#This Row],[HomeForecast]])^2 -> 23.758611
A15: Dallas Stars | B15: 0.21708031 | D15: New Jersey Devils | E15: ='NHL2025-26Results'!C11 -> 3 | F15: Carolina Hurricanes | G15: ='NHL2025-26Results'!E11 -> 6 | H15: =Table3[[#This Row],[G_1]]-Table3[[#This Row],[G]] -> 3 | I15: =HomeEdge+VLOOKUP(Table3[[#This Row],[Home]],$A$6:$B$38,2,FALSE)-VLOOKUP(Table3[[#This Row],[Visitor]],$A$6:$B$38,2,FALSE) -> 1.1072092 | J15: =(Table3[[#This Row],[HomeMargin]]-Table3[[#This Row],[HomeForecast]])^2 -> 3.5826569
A16: Detroit Red Wings | B16: -0.33113779 | D16: Utah Mammoth | E16: ='NHL2025-26Results'!C12 -> 1 | F16: Colorado Avalanche | G16: ='NHL2025-26Results'!E12 -> 2 | H16: =Table3[[#This Row],[G_1]]-Table3[[#This Row],[G]] -> 1 | I16: =HomeEdge+VLOOKUP(Table3[[#This Row],[Home]],$A$6:$B$38,2,FALSE)-VLOOKUP(Table3[[#This Row],[Visitor]],$A$6:$B$38,2,FALSE) -> 1.0441791 | J16: =(Table3[[#This Row],[HomeMargin]]-Table3[[#This Row],[HomeForecast]])^2 -> 0.0019517923
A17: Edmonton Oilers | B17: -0.36462595 | D17: Montreal Canadiens | E17: ='NHL2025-26Results'!C13 -> 5 | F17: Detroit Red Wings | G17: ='NHL2025-26Results'!E13 -> 1 | H17: =Table3[[#This Row],[G_1]]-Table3[[#This Row],[G]] -> -4 | I17: =HomeEdge+VLOOKUP(Table3[[#This Row],[Home]],$A$6:$B$38,2,FALSE)-VLOOKUP(Table3[[#This Row],[Visitor]],$A$6:$B$38,2,FALSE) -> -0.11525612 | J17: =(Table3[[#This Row],[HomeMargin]]-Table3[[#This Row],[HomeForecast]])^2 -> 15.091235
A18: Florida Panthers | B18: -0.55695213 | D18: Philadelphia Flyers | E18: ='NHL2025-26Results'!C14 -> 1 | F18: Florida Panthers | G18: ='NHL2025-26Results'!E14 -> 2 | H18: =Table3[[#This Row],[G_1]]-Table3[[#This Row],[G]] -> 1 | I18: =HomeEdge+VLOOKUP(Table3[[#This Row],[Home]],$A$6:$B$38,2,FALSE)-VLOOKUP(Table3[[#This Row],[Visitor]],$A$6:$B$38,2,FALSE) -> 0.12363419 | J18: =(Table3[[#This Row],[HomeMargin]]-Table3[[#This Row],[HomeForecast]])^2 -> 0.76801703
... A38: Winnipeg Jets | B38: -0.58845147 | D38: New York Rangers | E38: ='NHL2025-26Results'!C34 -> 6 | F38: Pittsburgh Penguins | G38: ='NHL2025-26Results'!E34 -> 1 | H38: =Table3[[#This Row],[G_1]]-Table3[[#This Row],[G]] -> -5 | I38: =HomeEdge+VLOOKUP(Table3[[#This Row],[Home]],$A$6:$B$38,2,FALSE)-VLOOKUP(Table3[[#This Row],[Visitor]],$A$6:$B$38,2,FALSE) -> 0.86616249 | J38: =(Table3[[#This Row],[HomeMargin]]-Table3[[#This Row],[HomeForecast]])^2 -> 34.411862
D39: Vegas Golden Knights | E39: ='NHL2025-26Results'!C35 -> 1 | F39: Seattle Kraken | G39: ='NHL2025-26Results'!E35 -> 2 | H39: =Table3[[#This Row],[G_1]]-Table3[[#This Row],[G]] -> 1 | I39: =HomeEdge+VLOOKUP(Table3[[#This Row],[Home]],$A$6:$B$38,2,FALSE)-VLOOKUP(Table3[[#This Row],[Visitor]],$A$6:$B$38,2,FALSE) -> -0.18979553 | J39: =(Table3[[#This Row],[HomeMargin]]-Table3[[#This Row],[HomeForecast]])^2 -> 1.4156134
D40: Anaheim Ducks | E40: ='NHL2025-26Results'!C36 -> 7 | F40: San Jose Sharks | G40: ='NHL2025-26Results'!E36 -> 6 | H40: =Table3[[#This Row],[G_1]]-Table3[[#This Row],[G]] -> -1 | I40: =HomeEdge+VLOOKUP(Table3[[#This Row],[Home]],$A$6:$B$38,2,FALSE)-VLOOKUP(Table3[[#This Row],[Visitor]],$A$6:$B$38,2,FALSE) -> -0.059153008 | J40: =(Table3[[#This Row],[HomeMargin]]-Table3[[#This Row],[HomeForecast]])^2 -> 0.88519306
D41: New Jersey Devils | E41: ='NHL2025-26Results'!C37 -> 5 | F41: Tampa Bay Lightning | G41: ='NHL2025-26Results'!E37 -> 3 | H41: =Table3[[#This Row],[G_1]]-Table3[[#This Row],[G]] -> -2 | I41: =HomeEdge+VLOOKUP(Table3[[#This Row],[Home]],$A$6:$B$38,2,FALSE)-VLOOKUP(Table3[[#This Row],[Visitor]],$A$6:$B$38,2,FALSE) -> 1.5957969 | J41: =(Table3[[#This Row],[HomeMargin]]-Table3[[#This Row],[HomeForecast]])^2 -> 12.929755
D42: Los Angeles Kings | E42: ='NHL2025-26Results'!C38 -> 2 | F42: Winnipeg Jets | G42: ='NHL2025-26Results'!E38 -> 3 | H42: =Table3[[#This Row],[G_1]]-Table3[[#This Row],[G]] -> 1 | I42: =HomeEdge+VLOOKUP(Table3[[#This Row],[Home]],$A$6:$B$38,2,FALSE)-VLOOKUP(Table3[[#This Row],[Visitor]],$A$6:$B$38,2,FALSE) -> 0.13185241 | J42: =(Table3[[#This Row],[HomeMargin]]-Table3[[#This Row],[HomeForecast]])^2 -> 0.75368023
D43: Washington Capitals | E43: ='NHL2025-26Results'!C39 -> 1 | F43: New York Rangers | G43: ='NHL2025-26Results'!E39 -> 0 | H43: =Table3[[#This Row],[G_1]]-Table3[[#This Row],[G]] -> -1 | I43: =HomeEdge+VLOOKUP(Table3[[#This Row],[Home]],$A$6:$B$38,2,FALSE)-VLOOKUP(Table3[[#This Row],[Visitor]],$A$6:$B$38,2,FALSE) -> -0.48713624 | J43: =(Table3[[#This Row],[HomeMargin]]-Table3[[#This Row],[HomeForecast]])^2 -> 0.26302924
D44: Tampa Bay Lightning | E44: ='NHL2025-26Results'!C40 -> 4 | F44: Boston Bruins | G44: ='NHL2025-26Results'!E40 -> 3 | H44: =Table3[[#This Row],[G_1]]-Table3[[#This Row],[G]] -> -1 | I44: =HomeEdge+VLOOKUP(Table3[[#This Row],[Home]],$A$6:$B$38,2,FALSE)-VLOOKUP(Table3[[#This Row],[Visitor]],$A$6:$B$38,2,FALSE) -> -0.69400547 | J44: =(Table3[[#This Row],[HomeMargin]]-Table3[[#This Row],[HomeForecast]])^2 -> 0.09363265
D45: Colorado Avalanche | E45: ='NHL2025-26Results'!C41 -> 3 | F45: Buffalo Sabres | G45: ='NHL2025-26Results'!E41 -> 1 | H45: =Table3[[#This Row],[G_1]]-Table3[[#This Row],[G]] -> -2 | I45: =HomeEdge+VLOOKUP(Table3[[#This Row],[Home]],$A$6:$B$38,2,FALSE)-VLOOKUP(Table3[[#This Row],[Visitor]],$A$6:$B$38,2,FALSE) -> -0.86090545 | J45: =(Table3[[#This Row],[HomeMargin]]-Table3[[#This Row],[HomeForecast]])^2 -> 1.2975364
D46: New Jersey Devils | E46: ='NHL2025-26Results'!C42 -> 3 | F46: Columbus Blue Jackets | G46: ='NHL2025-26Results'!E42 -> 2 | H46: =Table3[[#This Row],[G_1]]-Table3[[#This Row],[G]] -> -1 | I46: =HomeEdge+VLOOKUP(Table3[[#This Row],[Home]],$A$6:$B$38,2,FALSE)-VLOOKUP(Table3[[#This Row],[Visitor]],$A$6:$B$38,2,FALSE) -> 0.59315022 | J46: =(Table3[[#This Row],[HomeMargin]]-Table3[[#This Row],[HomeForecast]])^2 -> 2.5381276
D47: Utah Mammoth | E47: ='NHL2025-26Results'!C43 -> 1 | F47: Chicago Blackhawks | G47: ='NHL2025-26Results'!E43 -> 3 | H47: =Table3[[#This Row],[G_1]]-Table3[[#This Row],[G]] -> 2 | I47: =HomeEdge+VLOOKUP(Table3[[#This Row],[Home]],$A$6:$B$38,2,FALSE)-VLOOKUP(Table3[[#This Row],[Visitor]],$A$6:$B$38,2,FALSE) -> -0.88106852 | J47: =(Table3[[#This Row],[HomeMargin]]-Table3[[#This Row],[HomeForecast]])^2 -> 8.3005558
D48: Los Angeles Kings | E48: ='NHL2025-26Results'!C44 -> 3 | F48: Minnesota Wild | G48: ='NHL2025-26Results'!E44 -> 4 | H48: =Table3[[#This Row],[G_1]]-Table3[[#This Row],[G]] -> 1 | I48: =HomeEdge+VLOOKUP(Table3[[#This Row],[Home]],$A$6:$B$38,2,FALSE)-VLOOKUP(Table3[[#This Row],[Visitor]],$A$6:$B$38,2,FALSE) -> 0.78078917 | J48: =(Table3[[#This Row],[HomeMargin]]-Table3[[#This Row],[HomeForecast]])^2 -> 0.048053389
D49: Winnipeg Jets | E49: ='NHL2025-26Results'!C45 -> 5 | F49: New York Islanders | G49: ='NHL2025-26Results'!E45 -> 2 | H49: =Table3[[#This Row],[G_1]]-Table3[[#This Row],[G]] -> -3 | I49: =HomeEdge+VLOOKUP(Table3[[#This Row],[Home]],$A$6:$B$38,2,FALSE)-VLOOKUP(Table3[[#This Row],[Visitor]],$A$6:$B$38,2,FALSE) -> 0.53175383 | J49: =(Table3[[#This Row],[HomeMargin]]-Table3[[#This Row],[HomeForecast]])^2 -> 12.473285
D50: Nashville Predators | E50: ='NHL2025-26Results'!C46 -> 4 | F50: Ottawa Senators | G50: ='NHL2025-26Results'!E46 -> 1 | H50: =Table3[[#This Row],[G_1]]-Table3[[#This Row],[G]] -> -3 | I50: =HomeEdge+VLOOKUP(Table3[[#This Row],[Home]],$A$6:$B$38,2,FALSE)-VLOOKUP(Table3[[#This Row],[Visitor]],$A$6:$B$38,2,FALSE) -> 0.76006431 | J50: =(Table3[[#This Row],[HomeMargin]]-Table3[[#This Row],[HomeForecast]])^2 -> 14.138084
... D921: Philadelphia Flyers | E921: ='NHL2025-26Results'!C917 -> 1 | F921: Washington Capitals | G921: ='NHL2025-26Results'!E917 -> 3 | H921: =Table3[[#This Row],[G_1]]-Table3[[#This Row],[G]] -> 2 | I921: =HomeEdge+VLOOKUP(Table3[[#This Row],[Home]],$A$6:$B$38,2,FALSE)-VLOOKUP(Table3[[#This Row],[Visitor]],$A$6:$B$38,2,FALSE) -> 0.56081039 | J921: =(Table3[[#This Row],[HomeMargin]]-Table3[[#This Row],[HomeForecast]])^2 -> 2.0712667
D922: Columbus Blue Jackets | F922: Boston Bruins
D923: Tampa Bay Lightning | F923: Carolina Hurricanes
D924: Minnesota Wild | F924: Colorado Avalanche
D925: Toronto Maple Leafs | F925: Florida Panthers
D926: Edmonton Oilers | F926: Los Angeles Kings
D927: New York Islanders | F927: Montreal Canadiens
D928: Chicago Blackhawks | F928: Nashville Predators
D929: Philadelphia Flyers | F929: New York Rangers
D930: Detroit Red Wings | F930: Ottawa Senators
...

Sheet NHL HomeIce Model
A1: HomeEdge | B1: =HomeEdge -> 0.12960699 | D1: Date | E1: Time | F1: Home | G1: Home Differential | H1: Visitor | I1: Away Differential | J1: HomeIce Differential | K1: Predicted Winner | L1: Strength of Win | M1: Adjusted Correct | N1: Error | O1: Locked HomeIce Differential | P1: Locked Strength of Win | Q1: Locked Prediction | R1: Locked Correct
D2: 45937 | E2: 0.70833333 | F2: Florida Panthers | G2: =VLOOKUP(Table4[[#This Row],[Home]],'NHL Model'!$A$6:$B$38,2,FALSE) -> -0.55695213 | H2: Chicago Blackhawks | I2: =VLOOKUP(Table4[[#This Row],[Visitor]],'NHL Model'!$A$6:$B$38,2,FALSE) -> -0.92658078 | J2: =($B$1+Table4[[#This Row],[Home Differential]])-Table4[[#This Row],[Away Differential]] -> 0.49923564 | K2: =IF(Table4[[#This Row],[HomeIce Differential]]>0,Table4[[#This Row],[Home]],Table4[[#This Row],[Visitor]]) -> Florida Panthers | L2: =MAX(0, MIN(1,IF(Table4[[#This Row],[HomeIce Differential]]>0,((MAX(_xlfn.XLOOKUP(Table4[[#This Row],[Home]],Table1[[#All],[Team]],Table1[[#All],[HomeWin%]]), 0.54))/(MAX(_xlfn.XLOOKUP(Table4[[#This Row],[Home]],Table1[[#All],[Team]],Table1[[#All],[HomeWin%]]), 0.54)+MAX(_xlfn.XLOOKUP(Table4[[#This Row],[Visitor]],Table1[[#All],[Team]],Table1[[#All],[AwayWin%]]), 0.46)))+(Table4[[#This Row],[HomeIce Differential]]*$T$10),((MAX(_xlfn.XLOOKUP(Table4[[#This Row],[Visitor]],Table1[[#All],[Team]],Table1[[#All],[AwayWin%]]), 0.46))/(MAX(_xlfn.XLOOKUP(Table4[[#This Row],[Visitor]],Table1[[#All],[Team]],Table1[[#All],[AwayWin%]]), 0.46)+MAX(_xlfn.XLOOKUP(Table4[[#This Row],[Home]],Table1[[#All],[Team]],Table1[[#All],[HomeWin%]]), 0.54)))+(ABS(Table4[[#This Row],[HomeIce Differential]])*$T$10)))) -> 0.5960611 | M2: =IF(OR((NHL2025_26Results[[#This Row],[Winning Team]]="")),"-",IF(Table4[[#This Row],[Predicted Winner]]=NHL2025_26Results[[#This Row],[Winning Team]],"YES","NO")) -> YES | N2: =IF(Table4[[#This Row],[Adjusted Correct]]="-", "",IF(Table4[[#This Row],[Adjusted Correct]]="YES",(Table4[[#This Row],[Strength of Win]]-1)^2,(Table4[[#This Row],[Strength of Win]]-0)^2)) -> 0.16316664 | O2: 0.020105267 | Q2: Florida Panthers | R2: YES | T2: Live Accuracy | V2: Locked Accuracy
A3: Row Labels | B3: Sum of Rating | D3: 45937 | E3: 0.9375 | F3: Los Angeles Kings | G3: =VLOOKUP(Table4[[#This Row],[Home]],'NHL Model'!$A$6:$B$38,2,FALSE) -> -0.5906969 | H3: Colorado Avalanche | I3: =VLOOKUP(Table4[[#This Row],[Visitor]],'NHL Model'!$A$6:$B$38,2,FALSE) -> 0.99866683 | J3: =($B$1+Table4[[#This Row],[Home Differential]])-Table4[[#This Row],[Away Differential]] -> -1.4597567 | K3: =IF(Table4[[#This Row],[HomeIce Differential]]>0,Table4[[#This Row],[Home]],Table4[[#This Row],[Visitor]]) -> Colorado Avalanche | L3: =MAX(0, MIN(1,IF(Table4[[#This Row],[HomeIce Differential]]>0,((MAX(_xlfn.XLOOKUP(Table4[[#This Row],[Home]],Table1[[#All],[Team]],Table1[[#All],[HomeWin%]]), 0.54))/(MAX(_xlfn.XLOOKUP(Table4[[#This Row],[Home]],Table1[[#All],[Team]],Table1[[#All],[HomeWin%]]), 0.54)+MAX(_xlfn.XLOOKUP(Table4[[#This Row],[Visitor]],Table1[[#All],[Team]],Table1[[#All],[AwayWin%]]), 0.46)))+(Table4[[#This Row],[HomeIce Differential]]*$T$10),((MAX(_xlfn.XLOOKUP(Table4[[#This Row],[Visitor]],Table1[[#All],[Team]],Table1[[#All],[AwayWin%]]), 0.46))/(MAX(_xlfn.XLOOKUP(Table4[[#This Row],[Visitor]],Table1[[#All],[Team]],Table1[[#All],[AwayWin%]]), 0.46)+MAX(_xlfn.XLOOKUP(Table4[[#This Row],[Home]],Table1[[#All],[Team]],Table1[[#All],[HomeWin%]]), 0.54)))+(ABS(Table4[[#This Row],[HomeIce Differential]])*$T$10)))) -> 0.69318698 | M3: =IF(OR((NHL2025_26Results[[#This Row],[Winning Team]]="")),"-",IF(Table4[[#This Row],[Predicted Winner]]=NHL2025_26Results[[#This Row],[Winning Team]],"YES","NO")) -> YES | N3: =IF(Table4[[#This Row],[Adjusted Correct]]="-", "",IF(Table4[[#This Row],[Adjusted Correct]]="YES",(Table4[[#This Row],[Strength of Win]]-1)^2,(Table4[[#This Row],[Strength of Win]]-0)^2)) -> 0.094134227 | O3: -0.074443027 | Q3: Colorado Avalanche | R3: YES | T3: =COUNTIF(Table4[Adjusted Correct],"YES") -> 551 | V3: =COUNTIF(Table4[Locked Correct],"YES") -> 515
A4: Anaheim Ducks | B4: 0.43613316 | D4: 45937 | E4: 0.83333333 | F4: New York Rangers | G4: =VLOOKUP(Table4[[#This Row],[Home]],'NHL Model'!$A$6:$B$38,2,FALSE) -> -0.73651915 | H4: Pittsburgh Penguins | I4: =VLOOKUP(Table4[[#This Row],[Visitor]],'NHL Model'!$A$6:$B$38,2,FALSE) -> 3.6349513e-05 | J4: =($B$1+Table4[[#This Row],[Home Differential]])-Table4[[#This Row],[Away Differential]] -> -0.60694852 | K4: =IF(Table4[[#This Row],[HomeIce Differential]]>0,Table4[[#This Row],[Home]],Table4[[#This Row],[Visitor]]) -> Pittsburgh Penguins | L4: =MAX(0, MIN(1,IF(Table4[[#This Row],[HomeIce Differential]]>0,((MAX(_xlfn.XLOOKUP(Table4[[#This Row],[Home]],Table1[[#All],[Team]],Table1[[#All],[HomeWin%]]), 0.54))/(MAX(_xlfn.XLOOKUP(Table4[[#This Row],[Home]],Table1[[#All],[Team]],Table1[[#All],[HomeWin%]]), 0.54)+MAX(_xlfn.XLOOKUP(Table4[[#This Row],[Visitor]],Table1[[#All],[Team]],Table1[[#All],[AwayWin%]]), 0.46)))+(Table4[[#This Row],[HomeIce Differential]]*$T$10),((MAX(_xlfn.XLOOKUP(Table4[[#This Row],[Visitor]],Table1[[#All],[Team]],Table1[[#All],[AwayWin%]]), 0.46))/(MAX(_xlfn.XLOOKUP(Table4[[#This Row],[Visitor]],Table1[[#All],[Team]],Table1[[#All],[AwayWin%]]), 0.46)+MAX(_xlfn.XLOOKUP(Table4[[#This Row],[Home]],Table1[[#All],[Team]],Table1[[#All],[HomeWin%]]), 0.54)))+(ABS(Table4[[#This Row],[HomeIce Differential]])*$T$10)))) -> 0.58229541 | M4: =IF(OR((NHL2025_26Results[[#This Row],[Winning Team]]="")),"-",IF(Table4[[#This Row],[Predicted Winner]]=NHL2025_26Results[[#This Row],[Winning Team]],"YES","NO")) -> YES | N4: =IF(Table4[[#This Row],[Adjusted Correct]]="-", "",IF(Table4[[#This Row],[Adjusted Correct]]="YES",(Table4[[#This Row],[Strength of Win]]-1)^2,(Table4[[#This Row],[Strength of Win]]-0)^2)) -> 0.17447712 | O4: -0.073597467 | Q4: Pittsburgh Penguins | R4: YES | T4: =COUNTIF(Table4[Adjusted Correct],"NO") -> 365 | V4: =COUNTIF(Table4[Locked Correct],"NO") -> 401
A5: Boston Bruins | B5: 0.20397886 | D5: 45938 | E5: 0.91666667 | F5: Edmonton Oilers | G5: =VLOOKUP(Table4[[#This Row],[Home]],'NHL Model'!$A$6:$B$38,2,FALSE) -> -0.36462595 | H5: Calgary Flames | I5: =VLOOKUP(Table4[[#This Row],[Visitor]],'NHL Model'!$A$6:$B$38,2,FALSE) -> -0.89031222 | J5: =($B$1+Table4[[#This Row],[Home Differential]])-Table4[[#This Row],[Away Differential]] -> 0.65529325 | K5: =IF(Table4[[#This Row],[HomeIce Differential]]>0,Table4[[#This Row],[Home]],Table4[[#This Row],[Visitor]]) -> Edmonton Oilers | L5: =MAX(0, MIN(1,IF(Table4[[#This Row],[HomeIce Differential]]>0,((MAX(_xlfn.XLOOKUP(Table4[[#This Row],[Home]],Table1[[#All],[Team]],Table1[[#All],[HomeWin%]]), 0.54))/(MAX(_xlfn.XLOOKUP(Table4[[#This Row],[Home]],Table1[[#All],[Team]],Table1[[#All],[HomeWin%]]), 0.54)+MAX(_xlfn.XLOOKUP(Table4[[#This Row],[Visitor]],Table1[[#All],[Team]],Table1[[#All],[AwayWin%]]), 0.46)))+(Table4[[#This Row],[HomeIce Differential]]*$T$10),((MAX(_xlfn.XLOOKUP(Table4[[#This Row],[Visitor]],Table1[[#All],[Team]],Table1[[#All],[AwayWin%]]), 0.46))/(MAX(_xlfn.XLOOKUP(Table4[[#This Row],[Visitor]],Table1[[#All],[Team]],Table1[[#All],[AwayWin%]]), 0.46)+MAX(_xlfn.XLOOKUP(Table4[[#This Row],[Home]],Table1[[#All],[Team]],Table1[[#All],[HomeWin%]]), 0.54)))+(ABS(Table4[[#This Row],[HomeIce Differential]])*$T$10)))) -> 0.61358541 | M5: =IF(OR((NHL2025_26Results[[#This Row],[Winning Team]]="")),"-",IF(Table4[[#This Row],[Predicted Winner]]=NHL2025_26Results[[#This Row],[Winning Team]],"YES","NO")) -> NO | N5: =IF(Table4[[#This Row],[Adjusted Correct]]="-", "",IF(Table4[[#This Row],[Adjusted Correct]]="YES",(Table4[[#This Row],[Strength of Win]]-1)^2,(Table4[[#This Row],[Strength of Win]]-0)^2)) -> 0.37648706 | O5: -0.0041674768 | Q5: Calgary Flames | R5: YES | T5: =SUM(T3:T4) -> 916 | V5: =SUM(V3:V4) -> 916
A6: Buffalo Sabres | B6: -0.44950551 | D6: 45938 | E6: 0.79166667 | F6: Toronto Maple Leafs | G6: =VLOOKUP(Table4[[#This Row],[Home]],'NHL Model'!$A$6:$B$38,2,FALSE) -> -0.44228057 | H6: Montreal Canadiens | I6: =VLOOKUP(Table4[[#This Row],[Visitor]],'NHL Model'!$A$6:$B$38,2,FALSE) -> -0.086274677 | J6: =($B$1+Table4[[#This Row],[Home Differential]])-Table4[[#This Row],[Away Differential]] -> -0.22639891 | K6: =IF(Table4[[#This Row],[HomeIce Differential]]>0,Table4[[#This Row],[Home]],Table4[[#This Row],[Visitor]]) -> Montreal Canadiens | L6: =MAX(0, MIN(1,IF(Table4[[#This Row],[HomeIce Differential]]>0,((MAX(_xlfn.XLOOKUP(Table4[[#This Row],[Home]],Table1[[#All],[Team]],Table1[[#All],[HomeWin%]]), 0.54))/(MAX(_xlfn.XLOOKUP(Table4[[#This Row],[Home]],Table1[[#All],[Team]],Table1[[#All],[HomeWin%]]), 0.54)+MAX(_xlfn.XLOOKUP(Table4[[#This Row],[Visitor]],Table1[[#All],[Team]],Table1[[#All],[AwayWin%]]), 0.46)))+(Table4[[#This Row],[HomeIce Differential]]*$T$10),((MAX(_xlfn.XLOOKUP(Table4[[#This Row],[Visitor]],Table1[[#All],[Team]],Table1[[#All],[AwayWin%]]), 0.46))/(MAX(_xlfn.XLOOKUP(Table4[[#This Row],[Visitor]],Table1[[#All],[Team]],Table1[[#All],[AwayWin%]]), 0.46)+MAX(_xlfn.XLOOKUP(Table4[[#This Row],[Home]],Table1[[#All],[Team]],Table1[[#All],[HomeWin%]]), 0.54)))+(ABS(Table4[[#This Row],[HomeIce Differential]])*$T$10)))) -> 0.53079276 | M6: =IF(OR((NHL2025_26Results[[#This Row],[Winning Team]]="")),"-",IF(Table4[[#This Row],[Predicted Winner]]=NHL2025_26Results[[#This Row],[Winning Team]],"YES","NO")) -> NO | N6: =IF(Table4[[#This Row],[Adjusted Correct]]="-", "",IF(Table4[[#This Row],[Adjusted Correct]]="YES",(Table4[[#This Row],[Strength of Win]]-1)^2,(Table4[[#This Row],[Strength of Win]]-0)^2)) -> 0.28174095 | O6: -0.0044363714 | Q6: Montreal Canadiens | R6: NO | T6: =T3/T5 -> 0.60152838 | V6: =V3/V5 -> 0.56222707
A7: Calgary Flames | B7: -0.57192592 | D7: 45938 | E7: 0.91666667 | F7: Vegas Golden Knights | G7: =VLOOKUP(Table4[[#This Row],[Home]],'NHL Model'!$A$6:$B$38,2,FALSE) -> -0.16296463 | H7: Los Angeles Kings | I7: =VLOOKUP(Table4[[#This Row],[Visitor]],'NHL Model'!$A$6:$B$38,2,FALSE) -> -0.5906969 | J7: =($B$1+Table4[[#This Row],[Home Differential]])-Table4[[#This Row],[Away Differential]] -> 0.55733925 | K7: =IF(Table4[[#This Row],[HomeIce Differential]]>0,Table4[[#This Row],[Home]],Table4[[#This Row],[Visitor]]) -> Vegas Golden Knights | L7: =MAX(0, MIN(1,IF(Table4[[#This Row],[HomeIce Differential]]>0,((MAX(_xlfn.XLOOKUP(Table4[[#This Row],[Home]],Table1[[#All],[Team]],Table1[[#All],[HomeWin%]]), 0.54))/(MAX(_xlfn.XLOOKUP(Table4[[#This Row],[Home]],Table1[[#All],[Team]],Table1[[#All],[HomeWin%]]), 0.54)+MAX(_xlfn.XLOOKUP(Table4[[#This Row],[Visitor]],Table1[[#All],[Team]],Table1[[#All],[AwayWin%]]), 0.46)))+(Table4[[#This Row],[HomeIce Differential]]*$T$10),((MAX(_xlfn.XLOOKUP(Table4[[#This Row],[Visitor]],Table1[[#All],[Team]],Table1[[#All],[AwayWin%]]), 0.46))/(MAX(_xlfn.XLOOKUP(Table4[[#This Row],[Visitor]],Table1[[#All],[Team]],Table1[[#All],[AwayWin%]]), 0.46)+MAX(_xlfn.XLOOKUP(Table4[[#This Row],[Home]],Table1[[#All],[Team]],Table1[[#All],[HomeWin%]]), 0.54)))+(ABS(Table4[[#This Row],[HomeIce Differential]])*$T$10)))) -> 0.58181655 | M7: =IF(OR((NHL2025_26Results[[#This Row],[Winning Team]]="")),"-",IF(Table4[[#This Row],[Predicted Winner]]=NHL2025_26Results[[#This Row],[Winning Team]],"YES","NO")) -> NO | N7: =IF(Table4[[#This Row],[Adjusted Correct]]="-", "",IF(Table4[[#This Row],[Adjusted Correct]]="YES",(Table4[[#This Row],[Strength of Win]]-1)^2,(Table4[[#This Row],[Strength of Win]]-0)^2)) -> 0.3385105 | O7: 0.030320066 | Q7: Vegas Golden Knights | R7: NO | T7: SSE
A8: Carolina Hurricanes | B8: 0.49088808 | D8: 45938 | E8: 0.8125 | F8: Washington Capitals | G8: =VLOOKUP(Table4[[#This Row],[Home]],'NHL Model'!$A$6:$B$38,2,FALSE) -> -0.11977593 | H8: Boston Bruins | I8: =VLOOKUP(Table4[[#This Row],[Visitor]],'NHL Model'!$A$6:$B$38,2,FALSE) -> -0.10253061 | J8: =($B$1+Table4[[#This Row],[Home Differential]])-Table4[[#This Row],[Away Differential]] -> 0.11236167 | K8: =IF(Table4[[#This Row],[HomeIce Differential]]>0,Table4[[#This Row],[Home]],Table4[[#This Row],[Visitor]]) -> Washington Capitals | L8: =MAX(0, MIN(1,IF(Table4[[#This Row],[HomeIce Differential]]>0,((MAX(_xlfn.XLOOKUP(Table4[[#This Row],[Home]],Table1[[#All],[Team]],Table1[[#All],[HomeWin%]]), 0.54))/(MAX(_xlfn.XLOOKUP(Table4[[#This Row],[Home]],Table1[[#All],[Team]],Table1[[#All],[HomeWin%]]), 0.54)+MAX(_xlfn.XLOOKUP(Table4[[#This Row],[Visitor]],Table1[[#All],[Team]],Table1[[#All],[AwayWin%]]), 0.46)))+(Table4[[#This Row],[HomeIce Differential]]*$T$10),((MAX(_xlfn.XLOOKUP(Table4[[#This Row],[Visitor]],Table1[[#All],[Team]],Table1[[#All],[AwayWin%]]), 0.46))/(MAX(_xlfn.XLOOKUP(Table4[[#This Row],[Visitor]],Table1[[#All],[Team]],Table1[[#All],[AwayWin%]]), 0.46)+MAX(_xlfn.XLOOKUP(Table4[[#This Row],[Home]],Table1[[#All],[Team]],Table1[[#All],[HomeWin%]]), 0.54)))+(ABS(Table4[[#This Row],[HomeIce Differential]])*$T$10)))) -> 0.57058405 | M8: =IF(OR((NHL2025_26Results[[#This Row],[Winning Team]]="")),"-",IF(Table4[[#This Row],[Predicted Winner]]=NHL2025_26Results[[#This Row],[Winning Team]],"YES","NO")) -> NO | N8: =IF(Table4[[#This Row],[Adjusted Correct]]="-", "",IF(Table4[[#This Row],[Adjusted Correct]]="YES",(Table4[[#This Row],[Strength of Win]]-1)^2,(Table4[[#This Row],[Strength of Win]]-0)^2)) -> 0.32556616 | O8: -0.0049858231 | Q8: Boston Bruins | R8: YES | T8: =SUM(Table4[Error]) -> 216.17062 | V8: =COUNTIF(Table4[Locked Correct],"") -> 396
A9: Chicago Blackhawks | B9: -0.26132138 | D9: 45939 | E9: 0.79166667 | F9: Boston Bruins | G9: =VLOOKUP(Table4[[#This Row],[Home]],'NHL Model'!$A$6:$B$38,2,FALSE) -> -0.10253061 | H9: Chicago Blackhawks | I9: =VLOOKUP(Table4[[#This Row],[Visitor]],'NHL Model'!$A$6:$B$38,2,FALSE) -> -0.92658078 | J9: =($B$1+Table4[[#This Row],[Home Differential]])-Table4[[#This Row],[Away Differential]] -> 0.95365715 | K9: =IF(Table4[[#This Row],[HomeIce Differential]]>0,Table4[[#This Row],[Home]],Table4[[#This Row],[Visitor]]) -> Boston Bruins | L9: =MAX(0, MIN(1,IF(Table4[[#This Row],[HomeIce Differential]]>0,((MAX(_xlfn.XLOOKUP(Table4[[#This Row],[Home]],Table1[[#All],[Team]],Table1[[#All],[HomeWin%]]), 0.54))/(MAX(_xlfn.XLOOKUP(Table4[[#This Row],[Home]],Table1[[#All],[Team]],Table1[[#All],[HomeWin%]]), 0.54)+MAX(_xlfn.XLOOKUP(Table4[[#This Row],[Visitor]],Table1[[#All],[Team]],Table1[[#All],[AwayWin%]]), 0.46)))+(Table4[[#This Row],[HomeIce Differential]]*$T$10),((MAX(_xlfn.XLOOKUP(Table4[[#This Row],[Visitor]],Table1[[#All],[Team]],Table1[[#All],[AwayWin%]]), 0.46))/(MAX(_xlfn.XLOOKUP(Table4[[#This Row],[Visitor]],Table1[[#All],[Team]],Table1[[#All],[AwayWin%]]), 0.46)+MAX(_xlfn.XLOOKUP(Table4[[#This Row],[Home]],Table1[[#All],[Team]],Table1[[#All],[HomeWin%]]), 0.54)))+(ABS(Table4[[#This Row],[HomeIce Differential]])*$T$10)))) -> 0.69880583 | M9: =IF(OR((NHL2025_26Results[[#This Row],[Winning Team]]="")),"-",IF(Table4[[#This Row],[Predicted Winner]]=NHL2025_26Results[[#This Row],[Winning Team]],"YES","NO")) -> YES | N9: =IF(Table4[[#This Row],[Adjusted Correct]]="-", "",IF(Table4[[#This Row],[Adjusted Correct]]="YES",(Table4[[#This Row],[Strength of Win]]-1)^2,(Table4[[#This Row],[Strength of Win]]-0)^2)) -> 0.090717931 | O9: 0.0060525585 | Q9: Boston Bruins | R9: YES | T9: Weight
A10: Colorado Avalanche | B10: 1.6856887 | D10: 45939 | E10: 0.79166667 | F10: Buffalo Sabres | G10: =VLOOKUP(Table4[[#This Row],[Home]],'NHL Model'!$A$6:$B$38,2,FALSE) -> 0.0081543966 | H10: New York Rangers | I10: =VLOOKUP(Table4[[#This Row],[Visitor]],'NHL Model'!$A$6:$B$38,2,FALSE) -> -0.73651915 | J10: =($B$1+Table4[[#This Row],[Home Differential]])-Table4[[#This Row],[Away Differential]] -> 0.87428054 | K10: =IF(Table4[[#This Row],[HomeIce Differential]]>0,Table4[[#This Row],[Home]],Table4[[#This Row],[Visitor]]) -> Buffalo Sabres | L10: =MAX(0, MIN(1,IF(Table4[[#This Row],[HomeIce Differential]]>0,((MAX(_xlfn.XLOOKUP(Table4[[#This Row],[Home]],Table1[[#All],[Team]],Table1[[#All],[HomeWin%]]), 0.54))/(MAX(_xlfn.XLOOKUP(Table4[[#This Row],[Home]],Table1[[#All],[Team]],Table1[[#All],[HomeWin%]]), 0.54)+MAX(_xlfn.XLOOKUP(Table4[[#This Row],[Visitor]],Table1[[#All],[Team]],Table1[[#All],[AwayWin%]]), 0.46)))+(Table4[[#This Row],[HomeIce Differential]]*$T$10),((MAX(_xlfn.XLOOKUP(Table4[[#This Row],[Visitor]],Table1[[#All],[Team]],Table1[[#All],[AwayWin%]]), 0.46))/(MAX(_xlfn.XLOOKUP(Table4[[#This Row],[Visitor]],Table1[[#All],[Team]],Table1[[#All],[AwayWin%]]), 0.46)+MAX(_xlfn.XLOOKUP(Table4[[#This Row],[Home]],Table1[[#All],[Team]],Table1[[#All],[HomeWin%]]), 0.54)))+(ABS(Table4[[#This Row],[HomeIce Differential]])*$T$10)))) -> 0.63150967 | M10: =IF(OR((NHL2025_26Results[[#This Row],[Winning Team]]="")),"-",IF(Table4[[#This Row],[Predicted Winner]]=NHL2025_26Results[[#This Row],[Winning Team]],"YES","NO")) -> NO | N10: =IF(Table4[[#This Row],[Adjusted Correct]]="-", "",IF(Table4[[#This Row],[Adjusted Correct]]="YES",(Table4[[#This Row],[Strength of Win]]-1)^2,(Table4[[#This Row],[Strength of Win]]-0)^2)) -> 0.39880447 | O10: 0.028937639 | Q10: Buffalo Sabres | R10: NO | T10: 0.11229387
A11: Columbus Blue Jackets | B11: -0.25187088 | D11: 45939 | E11: 0.8125 | F11: Carolina Hurricanes | G11: =VLOOKUP(Table4[[#This Row],[Home]],'NHL Model'!$A$6:$B$38,2,FALSE) -> 0.2324942 | H11: New Jersey Devils | I11: =VLOOKUP(Table4[[#This Row],[Visitor]],'NHL Model'!$A$6:$B$38,2,FALSE) -> -0.74510804 | J11: =($B$1+Table4[[#This Row],[Home Differential]])-Table4[[#This Row],[Away Differential]] -> 1.1072092 | K11: =IF(Table4[[#This Row],[HomeIce Differential]]>0,Table4[[#This Row],[Home]],Table4[[#This Row],[Visitor]]) -> Carolina Hurricanes | L11: =MAX(0, MIN(1,IF(Table4[[#This Row],[HomeIce Differential]]>0,((MAX(_xlfn.XLOOKUP(Table4[[#This Row],[Home]],Table1[[#All],[Team]],Table1[[#All],[HomeWin%]]), 0.54))/(MAX(_xlfn.XLOOKUP(Table4[[#This Row],[Home]],Table1[[#All],[Team]],Table1[[#All],[HomeWin%]]), 0.54)+MAX(_xlfn.XLOOKUP(Table4[[#This Row],[Visitor]],Table1[[#All],[Team]],Table1[[#All],[AwayWin%]]), 0.46)))+(Table4[[#This Row],[HomeIce Differential]]*$T$10),((MAX(_xlfn.XLOOKUP(Table4[[#This Row],[Visitor]],Table1[[#All],[Team]],Table1[[#All],[AwayWin%]]), 0.46))/(MAX(_xlfn.XLOOKUP(Table4[[#This Row],[Visitor]],Table1[[#All],[Team]],Table1[[#All],[AwayWin%]]), 0.46)+MAX(_xlfn.XLOOKUP(Table4[[#This Row],[Home]],Table1[[#All],[Team]],Table1[[#All],[HomeWin%]]), 0.54)))+(ABS(Table4[[#This Row],[HomeIce Differential]])*$T$10)))) -> 0.69967527 | M11: =IF(OR((NHL2025_26Results[[#This Row],[Winning Team]]="")),"-",IF(Table4[[#This Row],[Predicted Winner]]=NHL2025_26Results[[#This Row],[Winning Team]],"YES","NO")) -> YES | N11: =IF(Table4[[#This Row],[Adjusted Correct]]="-", "",IF(Table4[[#This Row],[Adjusted Correct]]="YES",(Table4[[#This Row],[Strength of Win]]-1)^2,(Table4[[#This Row],[Strength of Win]]-0)^2)) -> 0.090194943 | O11: -0.0064941247 | Q11: New Jersey Devils | R11: NO
A12: Dallas Stars | B12: 0.85025762 | D12: 45939 | E12: 0.875 | F12: Colorado Avalanche | G12: =VLOOKUP(Table4[[#This Row],[Home]],'NHL Model'!$A$6:$B$38,2,FALSE) -> 0.99866683 | H12: Utah Mammoth | I12: =VLOOKUP(Table4[[#This Row],[Visitor]],'NHL Model'!$A$6:$B$38,2,FALSE) -> 0.084094726 | J12: =($B$1+Table4[[#This Row],[Home Differential]])-Table4[[#This Row],[Away Differential]] -> 1.0441791 | K12: =IF(Table4[[#This Row],[HomeIce Differential]]>0,Table4[[#This Row],[Home]],Table4[[#This Row],[Visitor]]) -> Colorado Avalanche | L12: =MAX(0, MIN(1,IF(Table4[[#This Row],[HomeIce Differential]]>0,((MAX(_xlfn.XLOOKUP(Table4[[#This Row],[Home]],Table1[[#All],[Team]],Table1[[#All],[HomeWin%]]), 0.54))/(MAX(_xlfn.XLOOKUP(Table4[[#This Row],[Home]],Table1[[#All],[Team]],Table1[[#All],[HomeWin%]]), 0.54)+MAX(_xlfn.XLOOKUP(Table4[[#This Row],[Visitor]],Table1[[#All],[Team]],Table1[[#All],[AwayWin%]]), 0.46)))+(Table4[[#This Row],[HomeIce Differential]]*$T$10),((MAX(_xlfn.XLOOKUP(Table4[[#This Row],[Visitor]],Table1[[#All],[Team]],Table1[[#All],[AwayWin%]]), 0.46))/(MAX(_xlfn.XLOOKUP(Table4[[#This Row],[Visitor]],Table1[[#All],[Team]],Table1[[#All],[AwayWin%]]), 0.46)+MAX(_xlfn.XLOOKUP(Table4[[#This Row],[Home]],Table1[[#All],[Team]],Table1[[#All],[HomeWin%]]), 0.54)))+(ABS(Table4[[#This Row],[HomeIce Differential]])*$T$10)))) -> 0.73708962 | M12: =IF(OR((NHL2025_26Results[[#This Row],[Winning Team]]="")),"-",IF(Table4[[#This Row],[Predicted Winner]]=NHL2025_26Results[[#This Row],[Winning Team]],"YES","NO")) -> YES | N12: =IF(Table4[[#This Row],[Adjusted Correct]]="-", "",IF(Table4[[#This Row],[Adjusted Correct]]="YES",(Table4[[#This Row],[Strength of Win]]-1)^2,(Table4[[#This Row],[Strength of Win]]-0)^2)) -> 0.069121869 | O12: 0.028930898 | Q12: Colorado Avalanche | R12: YES
A13: Detroit Red Wings | B13: -0.3555354 | D13: 45939 | E13: 0.79166667 | F13: Detroit Red Wings | G13: =VLOOKUP(Table4[[#This Row],[Home]],'NHL Model'!$A$6:$B$38,2,FALSE) -> -0.33113779 | H13: Montreal Canadiens | I13: =VLOOKUP(Table4[[#This Row],[Visitor]],'NHL Model'!$A$6:$B$38,2,FALSE) -> -0.086274677 | J13: =($B$1+Table4[[#This Row],[Home Differential]])-Table4[[#This Row],[Away Differential]] -> -0.11525612 | K13: =IF(Table4[[#This Row],[HomeIce Differential]]>0,Table4[[#This Row],[Home]],Table4[[#This Row],[Visitor]]) -> Montreal Canadiens | L13: =MAX(0, MIN(1,IF(Table4[[#This Row],[HomeIce Differential]]>0,((MAX(_xlfn.XLOOKUP(Table4[[#This Row],[Home]],Table1[[#All],[Team]],Table1[[#All],[HomeWin%]]), 0.54))/(MAX(_xlfn.XLOOKUP(Table4[[#This Row],[Home]],Table1[[#All],[Team]],Table1[[#All],[HomeWin%]]), 0.54)+MAX(_xlfn.XLOOKUP(Table4[[#This Row],[Visitor]],Table1[[#All],[Team]],Table1[[#All],[AwayWin%]]), 0.46)))+(Table4[[#This Row],[HomeIce Differential]]*$T$10),((MAX(_xlfn.XLOOKUP(Table4[[#This Row],[Visitor]],Table1[[#All],[Team]],Table1[[#All],[AwayWin%]]), 0.46))/(MAX(_xlfn.XLOOKUP(Table4[[#This Row],[Visitor]],Table1[[#All],[Team]],Table1[[#All],[AwayWin%]]), 0.46)+MAX(_xlfn.XLOOKUP(Table4[[#This Row],[Home]],Table1[[#All],[Team]],Table1[[#All],[HomeWin%]]), 0.54)))+(ABS(Table4[[#This Row],[HomeIce Differential]])*$T$10)))) -> 0.49198447 | M13: =IF(OR((NHL2025_26Results[[#This Row],[Winning Team]]="")),"-",IF(Table4[[#This Row],[Predicted Winner]]=NHL2025_26Results[[#This Row],[Winning Team]],"YES","NO")) -> YES | N13: =IF(Table4[[#This Row],[Adjusted Correct]]="-", "",IF(Table4[[#This Row],[Adjusted Correct]]="YES",(Table4[[#This Row],[Strength of Win]]-1)^2,(Table4[[#This Row],[Strength of Win]]-0)^2)) -> 0.25807978 | O13: -0.0059607629 | Q13: Montreal Canadiens | R13: YES
A14: Edmonton Oilers | B14: -0.21956254 | D14: 45939 | E14: 0.79166667 | F14: Florida Panthers | G14: =VLOOKUP(Table4[[#This Row],[Home]],'NHL Model'!$A$6:$B$38,2,FALSE) -> -0.55695213 | H14: Philadelphia Flyers | I14: =VLOOKUP(Table4[[#This Row],[Visitor]],'NHL Model'!$A$6:$B$38,2,FALSE) -> -0.55097934 | J14: =($B$1+Table4[[#This Row],[Home Differential]])-Table4[[#This Row],[Away Differential]] -> 0.12363419 | K14: =IF(Table4[[#This Row],[HomeIce Differential]]>0,Table4[[#This Row],[Home]],Table4[[#This Row],[Visitor]]) -> Florida Panthers | L14: =MAX(0, MIN(1,IF(Table4[[#This Row],[HomeIce Differential]]>0,((MAX(_xlfn.XLOOKUP(Table4[[#This Row],[Home]],Table1[[#All],[Team]],Table1[[#All],[HomeWin%]]), 0.54))/(MAX(_xlfn.XLOOKUP(Table4[[#This Row],[Home]],Table1[[#All],[Team]],Table1[[#All],[HomeWin%]]), 0.54)+MAX(_xlfn.XLOOKUP(Table4[[#This Row],[Visitor]],Table1[[#All],[Team]],Table1[[#All],[AwayWin%]]), 0.46)))+(Table4[[#This Row],[HomeIce Differential]]*$T$10),((MAX(_xlfn.XLOOKUP(Table4[[#This Row],[Visitor]],Table1[[#All],[Team]],Table1[[#All],[AwayWin%]]), 0.46))/(MAX(_xlfn.XLOOKUP(Table4[[#This Row],[Visitor]],Table1[[#All],[Team]],Table1[[#All],[AwayWin%]]), 0.46)+MAX(_xlfn.XLOOKUP(Table4[[#This Row],[Home]],Table1[[#All],[Team]],Table1[[#All],[HomeWin%]]), 0.54)))+(ABS(Table4[[#This Row],[HomeIce Differential]])*$T$10)))) -> 0.55388336 | M14: =IF(OR((NHL2025_26Results[[#This Row],[Winning Team]]="")),"-",IF(Table4[[#This Row],[Predicted Winner]]=NHL2025_26Results[[#This Row],[Winning Team]],"YES","NO")) -> YES | N14: =IF(Table4[[#This Row],[Adjusted Correct]]="-", "",IF(Table4[[#This Row],[Adjusted Correct]]="YES",(Table4[[#This Row],[Strength of Win]]-1)^2,(Table4[[#This Row],[Strength of Win]]-0)^2)) -> 0.19902006 | O14: 0.0056848249 | Q14: Florida Panthers | R14: YES
A15: Florida Panthers | B15: -0.10058358 | D15: 45939 | E15: 0.83333333 | F15: Nashville Predators | G15: =VLOOKUP(Table4[[#This Row],[Home]],'NHL Model'!$A$6:$B$38,2,FALSE) -> -0.82056481 | H15: Columbus Blue Jackets | I15: =VLOOKUP(Table4[[#This Row],[Visitor]],'NHL Model'!$A$6:$B$38,2,FALSE) -> -0.2815648 | J15: =($B$1+Table4[[#This Row],[Home Differential]])-Table4[[#This Row],[Away Differential]] -> -0.40939303 | K15: =IF(Table4[[#This Row],[HomeIce Differential]]>0,Table4[[#This Row],[Home]],Table4[[#This Row],[Visitor]]) -> Columbus Blue Jackets | L15: =MAX(0, MIN(1,IF(Table4[[#This Row],[HomeIce Differential]]>0,((MAX(_xlfn.XLOOKUP(Table4[[#This Row],[Home]],Table1[[#All],[Team]],Table1[[#All],[HomeWin%]]), 0.54))/(MAX(_xlfn.XLOOKUP(Table4[[#This Row],[Home]],Table1[[#All],[Team]],Table1[[#All],[HomeWin%]]), 0.54)+MAX(_xlfn.XLOOKUP(Table4[[#This Row],[Visitor]],Table1[[#All],[Team]],Table1[[#All],[AwayWin%]]), 0.46)))+(Table4[[#This Row],[HomeIce Differential]]*$T$10),((MAX(_xlfn.XLOOKUP(Table4[[#This Row],[Visitor]],Table1[[#All],[Team]],Table1[[#All],[AwayWin%]]), 0.46))/(MAX(_xlfn.XLOOKUP(Table4[[#This Row],[Visitor]],Table1[[#All],[Team]],Table1[[#All],[AwayWin%]]), 0.46)+MAX(_xlfn.XLOOKUP(Table4[[#This Row],[Home]],Table1[[#All],[Team]],Table1[[#All],[HomeWin%]]), 0.54)))+(ABS(Table4[[#This Row],[HomeIce Differential]])*$T$10)))) -> 0.51798851 | M15: =IF(OR((NHL2025_26Results[[#This Row],[Winning Team]]="")),"-",IF(Table4[[#This Row],[Predicted Winner]]=NHL2025_26Results[[#This Row],[Winning Team]],"YES","NO")) -> NO | N15: =IF(Table4[[#This Row],[Adjusted Correct]]="-", "",IF(Table4[[#This Row],[Adjusted Correct]]="YES",(Table4[[#This Row],[Strength of Win]]-1)^2,(Table4[[#This Row],[Strength of Win]]-0)^2)) -> 0.2683121 | O15: -0.0066115256 | Q15: Columbus Blue Jackets | R15: NO
A16: Los Angeles Kings | B16: 0.15754466 | D16: 45939 | E16: 0.79166667 | F16: Pittsburgh Penguins | G16: =VLOOKUP(Table4[[#This Row],[Home]],'NHL Model'!$A$6:$B$38,2,FALSE) -> 3.6349513e-05 | H16: New York Islanders | I16: =VLOOKUP(Table4[[#This Row],[Visitor]],'NHL Model'!$A$6:$B$38,2,FALSE) -> -0.18630463 | J16: =($B$1+Table4[[#This Row],[Home Differential]])-Table4[[#This Row],[Away Differential]] -> 0.31594796 | K16: =IF(Table4[[#This Row],[HomeIce Differential]]>0,Table4[[#This Row],[Home]],Table4[[#This Row],[Visitor]]) -> Pittsburgh Penguins | L16: =MAX(0, MIN(1,IF(Table4[[#This Row],[HomeIce Differential]]>0,((MAX(_xlfn.XLOOKUP(Table4[[#This Row],[Home]],Table1[[#All],[Team]],Table1[[#All],[HomeWin%]]), 0.54))/(MAX(_xlfn.XLOOKUP(Table4[[#This Row],[Home]],Table1[[#All],[Team]],Table1[[#All],[HomeWin%]]), 0.54)+MAX(_xlfn.XLOOKUP(Table4[[#This Row],[Visitor]],Table1[[#All],[Team]],Table1[[#All],[AwayWin%]]), 0.46)))+(Table4[[#This Row],[HomeIce Differential]]*$T$10),((MAX(_xlfn.XLOOKUP(Table4[[#This Row],[Visitor]],Table1[[#All],[Team]],Table1[[#All],[AwayWin%]]), 0.46))/(MAX(_xlfn.XLOOKUP(Table4[[#This Row],[Visitor]],Table1[[#All],[Team]],Table1[[#All],[AwayWin%]]), 0.46)+MAX(_xlfn.XLOOKUP(Table4[[#This Row],[Home]],Table1[[#All],[Team]],Table1[[#All],[HomeWin%]]), 0.54)))+(ABS(Table4[[#This Row],[HomeIce Differential]])*$T$10)))) -> 0.53858461 | M16: =IF(OR((NHL2025_26Results[[#This Row],[Winning Team]]="")),"-",IF(Table4[[#This Row],[Predicted Winner]]=NHL2025_26Results[[#This Row],[Winning Team]],"YES","NO")) -> YES | N16: =IF(Table4[[#This Row],[Adjusted Correct]]="-", "",IF(Table4[[#This Row],[Adjusted Correct]]="YES",(Table4[[#This Row],[Strength of Win]]-1)^2,(Table4[[#This Row],[Strength of Win]]-0)^2)) -> 0.21290416 | O16: 0.029201412 | Q16: Pittsburgh Penguins | R16: YES
A17: Minnesota Wild | B17: 0.11674568 | D17: 45939 | E17: 0.91666667 | F17: Seattle Kraken | G17: =VLOOKUP(Table4[[#This Row],[Home]],'NHL Model'!$A$6:$B$38,2,FALSE) -> -0.48236715 | H17: Anaheim Ducks | I17: =VLOOKUP(Table4[[#This Row],[Visitor]],'NHL Model'!$A$6:$B$38,2,FALSE) -> -0.46360583 | J17: =($B$1+Table4[[#This Row],[Home Differential]])-Table4[[#This Row],[Away Differential]] -> 0.11084566 | K17: =IF(Table4[[#This Row],[HomeIce Differential]]>0,Table4[[#This Row],[Home]],Table4[[#This Row],[Visitor]]) -> Seattle Kraken | L17: =MAX(0, MIN(1,IF(Table4[[#This Row],[HomeIce Differential]]>0,((MAX(_xlfn.XLOOKUP(Table4[[#This Row],[Home]],Table1[[#All],[Team]],Table1[[#All],[HomeWin%]]), 0.54))/(MAX(_xlfn.XLOOKUP(Table4[[#This Row],[Home]],Table1[[#All],[Team]],Table1[[#All],[HomeWin%]]), 0.54)+MAX(_xlfn.XLOOKUP(Table4[[#This Row],[Visitor]],Table1[[#All],[Team]],Table1[[#All],[AwayWin%]]), 0.46)))+(Table4[[#This Row],[HomeIce Differential]]*$T$10),((MAX(_xlfn.XLOOKUP(Table4[[#This Row],[Visitor]],Table1[[#All],[Team]],Table1[[#All],[AwayWin%]]), 0.46))/(MAX(_xlfn.XLOOKUP(Table4[[#This Row],[Visitor]],Table1[[#All],[Team]],Table1[[#All],[AwayWin%]]), 0.46)+MAX(_xlfn.XLOOKUP(Table4[[#This Row],[Home]],Table1[[#All],[Team]],Table1[[#All],[HomeWin%]]), 0.54)))+(ABS(Table4[[#This Row],[HomeIce Differential]])*$T$10)))) -> 0.55244729 | M17: =IF(OR((NHL2025_26Results[[#This Row],[Winning Team]]="")),"-",IF(Table4[[#This Row],[Predicted Winner]]=NHL2025_26Results[[#This Row],[Winning Team]],"YES","NO")) -> YES | N17: =IF(Table4[[#This Row],[Adjusted Correct]]="-", "",IF(Table4[[#This Row],[Adjusted Correct]]="YES",(Table4[[#This Row],[Strength of Win]]-1)^2,(Table4[[#This Row],[Strength of Win]]-0)^2)) -> 0.20030343 | O17: -0.0060975677 | Q17: Anaheim Ducks | R17: NO
A18: Montreal Canadiens | B18: -0.31957555 | D18: 45939 | E18: 0.91666667 | F18: San Jose Sharks | G18: =VLOOKUP(Table4[[#This Row],[Home]],'NHL Model'!$A$6:$B$38,2,FALSE) -> -0.65236582 | H18: Vegas Golden Knights | I18: =VLOOKUP(Table4[[#This Row],[Visitor]],'NHL Model'!$A$6:$B$38,2,FALSE) -> -0.16296463 | J18: =($B$1+Table4[[#This Row],[Home Differential]])-Table4[[#This Row],[Away Differential]] -> -0.3597942 | K18: =IF(Table4[[#This Row],[HomeIce Differential]]>0,Table4[[#This Row],[Home]],Table4[[#This Row],[Visitor]]) -> Vegas Golden Knights | L18: =MAX(0, MIN(1,IF(Table4[[#This Row],[HomeIce Differential]]>0,((MAX(_xlfn.XLOOKUP(Table4[[#This Row],[Home]],Table1[[#All],[Team]],Table1[[#All],[HomeWin%]]), 0.54))/(MAX(_xlfn.XLOOKUP(Table4[[#This Row],[Home]],Table1[[#All],[Team]],Table1[[#All],[HomeWin%]]), 0.54)+MAX(_xlfn.XLOOKUP(Table4[[#This Row],[Visitor]],Table1[[#All],[Team]],Table1[[#All],[AwayWin%]]), 0.46)))+(Table4[[#This Row],[HomeIce Differential]]*$T$10),((MAX(_xlfn.XLOOKUP(Table4[[#This Row],[Visitor]],Table1[[#All],[Team]],Table1[[#All],[AwayWin%]]), 0.46))/(MAX(_xlfn.XLOOKUP(Table4[[#This Row],[Visitor]],Table1[[#All],[Team]],Table1[[#All],[AwayWin%]]), 0.46)+MAX(_xlfn.XLOOKUP(Table4[[#This Row],[Home]],Table1[[#All],[Team]],Table1[[#All],[HomeWin%]]), 0.54)))+(ABS(Table4[[#This Row],[HomeIce Differential]])*$T$10)))) -> 0.51241887 | M18: =IF(OR((NHL2025_26Results[[#This Row],[Winning Team]]="")),"-",IF(Table4[[#This Row],[Predicted Winner]]=NHL2025_26Results[[#This Row],[Winning Team]],"YES","NO")) -> YES | N18: =IF(Table4[[#This Row],[Adjusted Correct]]="-", "",IF(Table4[[#This Row],[Adjusted Correct]]="YES",(Table4[[#This Row],[Strength of Win]]-1)^2,(Table4[[#This Row],[Strength of Win]]-0)^2)) -> 0.23773536 | O18: -0.0056918684 | Q18: Vegas Golden Knights | R18: YES
A19: Nashville Predators | B19: -0.87778808 | D19: 45939 | E19: 0.83333333 | F19: St. Louis Blues | G19: =VLOOKUP(Table4[[#This Row],[Home]],'NHL Model'!$A$6:$B$38,2,FALSE) -> -1.3128573 | H19: Minnesota Wild | I19: =VLOOKUP(Table4[[#This Row],[Visitor]],'NHL Model'!$A$6:$B$38,2,FALSE) -> 0.060485284 | J19: =($B$1+Table4[[#This Row],[Home Differential]])-Table4[[#This Row],[Away Differential]] -> -1.2437356 | K19: =IF(Table4[[#This Row],[HomeIce Differential]]>0,Table4[[#This Row],[Home]],Table4[[#This Row],[Visitor]]) -> Minnesota Wild | L19: =MAX(0, MIN(1,IF(Table4[[#This Row],[HomeIce Differential]]>0,((MAX(_xlfn.XLOOKUP(Table4[[#This Row],[Home]],Table1[[#All],[Team]],Table1[[#All],[HomeWin%]]), 0.54))/(MAX(_xlfn.XLOOKUP(Table4[[#This Row],[Home]],Table1[[#All],[Team]],Table1[[#All],[HomeWin%]]), 0.54)+MAX(_xlfn.XLOOKUP(Table4[[#This Row],[Visitor]],Table1[[#All],[Team]],Table1[[#All],[AwayWin%]]), 0.46)))+(Table4[[#This Row],[HomeIce Differential]]*$T$10),((MAX(_xlfn.XLOOKUP(Table4[[#This Row],[Visitor]],Table1[[#All],[Team]],Table1[[#All],[AwayWin%]]), 0.46))/(MAX(_xlfn.XLOOKUP(Table4[[#This Row],[Visitor]],Table1[[#All],[Team]],Table1[[#All],[AwayWin%]]), 0.46)+MAX(_xlfn.XLOOKUP(Table4[[#This Row],[Home]],Table1[[#All],[Team]],Table1[[#All],[HomeWin%]]), 0.54)))+(ABS(Table4[[#This Row],[HomeIce Differential]])*$T$10)))) -> 0.66892913 | M19: =IF(OR((NHL2025_26Results[[#This Row],[Winning Team]]="")),"-",IF(Table4[[#This Row],[Predicted Winner]]=NHL2025_26Results[[#This Row],[Winning Team]],"YES","NO")) -> YES | N19: =IF(Table4[[#This Row],[Adjusted Correct]]="-", "",IF(Table4[[#This Row],[Adjusted Correct]]="YES",(Table4[[#This Row],[Strength of Win]]-1)^2,(Table4[[#This Row],[Strength of Win]]-0)^2)) -> 0.10960792 | O19: -0.0065095534 | Q19: Minnesota Wild | R19: YES
A20: New Jersey Devils | B20: -0.00030328718 | D20: 45939 | E20: 0.79166667 | F20: Tampa Bay Lightning | G20: =VLOOKUP(Table4[[#This Row],[Home]],'NHL Model'!$A$6:$B$38,2,FALSE) -> 0.72108185 | H20: Ottawa Senators | I20: =VLOOKUP(Table4[[#This Row],[Visitor]],'NHL Model'!$A$6:$B$38,2,FALSE) -> -0.19010748 | J20: =($B$1+Table4[[#This Row],[Home Differential]])-Table4[[#This Row],[Away Differential]] -> 1.0407963 | K20: =IF(Table4[[#This Row],[HomeIce Differential]]>0,Table4[[#This Row],[Home]],Table4[[#This Row],[Visitor]]) -> Tampa Bay Lightning | L20: =MAX(0, MIN(1,IF(Table4[[#This Row],[HomeIce Differential]]>0,((MAX(_xlfn.XLOOKUP(Table4[[#This Row],[Home]],Table1[[#All],[Team]],Table1[[#All],[HomeWin%]]), 0.54))/(MAX(_xlfn.XLOOKUP(Table4[[#This Row],[Home]],Table1[[#All],[Team]],Table1[[#All],[HomeWin%]]), 0.54)+MAX(_xlfn.XLOOKUP(Table4[[#This Row],[Visitor]],Table1[[#All],[Team]],Table1[[#All],[AwayWin%]]), 0.46)))+(Table4[[#This Row],[HomeIce Differential]]*$T$10),((MAX(_xlfn.XLOOKUP(Table4[[#This Row],[Visitor]],Table1[[#All],[Team]],Table1[[#All],[AwayWin%]]), 0.46))/(MAX(_xlfn.XLOOKUP(Table4[[#This Row],[Visitor]],Table1[[#All],[Team]],Table1[[#All],[AwayWin%]]), 0.46)+MAX(_xlfn.XLOOKUP(Table4[[#This Row],[Home]],Table1[[#All],[Team]],Table1[[#All],[HomeWin%]]), 0.54)))+(ABS(Table4[[#This Row],[HomeIce Differential]])*$T$10)))) -> 0.70118045 | M20: =IF(OR((NHL2025_26Results[[#This Row],[Winning Team]]="")),"-",IF(Table4[[#This Row],[Predicted Winner]]=NHL2025_26Results[[#This Row],[Winning Team]],"YES","NO")) -> NO | N20: =IF(Table4[[#This Row],[Adjusted Correct]]="-", "",IF(Table4[[#This Row],[Adjusted Correct]]="YES",(Table4[[#This Row],[Strength of Win]]-1)^2,(Table4[[#This Row],[Strength of Win]]-0)^2)) -> 0.49165402 | O20: -0.0060975919 | Q20: Ottawa Senators | R20: YES
A21: New York Islanders | B21: 0.29798772 | D21: 45939 | E21: 0.91666667 | F21: Vancouver Canucks | G21: =VLOOKUP(Table4[[#This Row],[Home]],'NHL Model'!$A$6:$B$38,2,FALSE) -> -1.3920033 | H21: Calgary Flames | I21: =VLOOKUP(Table4[[#This Row],[Visitor]],'NHL Model'!$A$6:$B$38,2,FALSE) -> -0.89031222 | J21: =($B$1+Table4[[#This Row],[Home Differential]])-Table4[[#This Row],[Away Differential]] -> -0.3720841 | K21: =IF(Table4[[#This Row],[HomeIce Differential]]>0,Table4[[#This Row],[Home]],Table4[[#This Row],[Visitor]]) -> Calgary Flames | L21: =MAX(0, MIN(1,IF(Table4[[#This Row],[HomeIce Differential]]>0,((MAX(_xlfn.XLOOKUP(Table4[[#This Row],[Home]],Table1[[#All],[Team]],Table1[[#All],[HomeWin%]]), 0.54))/(MAX(_xlfn.XLOOKUP(Table4[[#This Row],[Home]],Table1[[#All],[Team]],Table1[[#All],[HomeWin%]]), 0.54)+MAX(_xlfn.XLOOKUP(Table4[[#This Row],[Visitor]],Table1[[#All],[Team]],Table1[[#All],[AwayWin%]]), 0.46)))+(Table4[[#This Row],[HomeIce Differential]]*$T$10),((MAX(_xlfn.XLOOKUP(Table4[[#This Row],[Visitor]],Table1[[#All],[Team]],Table1[[#All],[AwayWin%]]), 0.46))/(MAX(_xlfn.XLOOKUP(Table4[[#This Row],[Visitor]],Table1[[#All],[Team]],Table1[[#All],[AwayWin%]]), 0.46)+MAX(_xlfn.XLOOKUP(Table4[[#This Row],[Home]],Table1[[#All],[Team]],Table1[[#All],[HomeWin%]]), 0.54)))+(ABS(Table4[[#This Row],[HomeIce Differential]])*$T$10)))) -> 0.50178276 | M21: =IF(OR((NHL2025_26Results[[#This Row],[Winning Team]]="")),"-",IF(Table4[[#This Row],[Predicted Winner]]=NHL2025_26Results[[#This Row],[Winning Team]],"YES","NO")) -> NO | N21: =IF(Table4[[#This Row],[Adjusted Correct]]="-", "",IF(Table4[[#This Row],[Adjusted Correct]]="YES",(Table4[[#This Row],[Strength of Win]]-1)^2,(Table4[[#This Row],[Strength of Win]]-0)^2)) -> 0.25178594 | O21: -0.0060976402 | Q21: Calgary Flames | R21: NO
A22: New York Rangers | B22: 0.1580802 | D22: 45939 | E22: 0.83333333 | F22: Winnipeg Jets | G22: =VLOOKUP(Table4[[#This Row],[Home]],'NHL Model'!$A$6:$B$38,2,FALSE) -> -0.58845147 | H22: Dallas Stars | I22: =VLOOKUP(Table4[[#This Row],[Visitor]],'NHL Model'!$A$6:$B$38,2,FALSE) -> 0.21708031 | J22: =($B$1+Table4[[#This Row],[Home Differential]])-Table4[[#This Row],[Away Differential]] -> -0.67592479 | K22: =IF(Table4[[#This Row],[HomeIce Differential]]>0,Table4[[#This Row],[Home]],Table4[[#This Row],[Visitor]]) -> Dallas Stars | L22: =MAX(0, MIN(1,IF(Table4[[#This Row],[HomeIce Differential]]>0,((MAX(_xlfn.XLOOKUP(Table4[[#This Row],[Home]],Table1[[#All],[Team]],Table1[[#All],[HomeWin%]]), 0.54))/(MAX(_xlfn.XLOOKUP(Table4[[#This Row],[Home]],Table1[[#All],[Team]],Table1[[#All],[HomeWin%]]), 0.54)+MAX(_xlfn.XLOOKUP(Table4[[#This Row],[Visitor]],Table1[[#All],[Team]],Table1[[#All],[AwayWin%]]), 0.46)))+(Table4[[#This Row],[HomeIce Differential]]*$T$10),((MAX(_xlfn.XLOOKUP(Table4[[#This Row],[Visitor]],Table1[[#All],[Team]],Table1[[#All],[AwayWin%]]), 0.46))/(MAX(_xlfn.XLOOKUP(Table4[[#This Row],[Visitor]],Table1[[#All],[Team]],Table1[[#All],[AwayWin%]]), 0.46)+MAX(_xlfn.XLOOKUP(Table4[[#This Row],[Home]],Table1[[#All],[Team]],Table1[[#All],[HomeWin%]]), 0.54)))+(ABS(Table4[[#This Row],[HomeIce Differential]])*$T$10)))) -> 0.59403692 | M22: =IF(OR((NHL2025_26Results[[#This Row],[Winning Team]]="")),"-",IF(Table4[[#This Row],[Predicted Winner]]=NHL2025_26Results[[#This Row],[Winning Team]],"YES","NO")) -> YES | N22: =IF(Table4[[#This Row],[Adjusted Correct]]="-", "",IF(Table4[[#This Row],[Adjusted Correct]]="YES",(Table4[[#This Row],[Strength of Win]]-1)^2,(Table4[[#This Row],[Strength of Win]]-0)^2)) -> 0.16480602 | O22: -0.0062374432 | Q22: Dallas Stars | R22: YES
... A36: Grand Total | B36: 0.36153635 | D36: 45941 | E36: 0.91666667 | F36: San Jose Sharks | G36: =VLOOKUP(Table4[[#This Row],[Home]],'NHL Model'!$A$6:$B$38,2,FALSE) -> -0.65236582 | H36: Anaheim Ducks | I36: =VLOOKUP(Table4[[#This Row],[Visitor]],'NHL Model'!$A$6:$B$38,2,FALSE) -> -0.46360583 | J36: =($B$1+Table4[[#This Row],[Home Differential]])-Table4[[#This Row],[Away Differential]] -> -0.059153008 | K36: =IF(Table4[[#This Row],[HomeIce Differential]]>0,Table4[[#This Row],[Home]],Table4[[#This Row],[Visitor]]) -> Anaheim Ducks | L36: =MAX(0, MIN(1,IF(Table4[[#This Row],[HomeIce Differential]]>0,((MAX(_xlfn.XLOOKUP(Table4[[#This Row],[Home]],Table1[[#All],[Team]],Table1[[#All],[HomeWin%]]), 0.54))/(MAX(_xlfn.XLOOKUP(Table4[[#This Row],[Home]],Table1[[#All],[Team]],Table1[[#All],[HomeWin%]]), 0.54)+MAX(_xlfn.XLOOKUP(Table4[[#This Row],[Visitor]],Table1[[#All],[Team]],Table1[[#All],[AwayWin%]]), 0.46)))+(Table4[[#This Row],[HomeIce Differential]]*$T$10),((MAX(_xlfn.XLOOKUP(Table4[[#This Row],[Visitor]],Table1[[#All],[Team]],Table1[[#All],[AwayWin%]]), 0.46))/(MAX(_xlfn.XLOOKUP(Table4[[#This Row],[Visitor]],Table1[[#All],[Team]],Table1[[#All],[AwayWin%]]), 0.46)+MAX(_xlfn.XLOOKUP(Table4[[#This Row],[Home]],Table1[[#All],[Team]],Table1[[#All],[HomeWin%]]), 0.54)))+(ABS(Table4[[#This Row],[HomeIce Differential]])*$T$10)))) -> 0.46664252 | M36: =IF(OR((NHL2025_26Results[[#This Row],[Winning Team]]="")),"-",IF(Table4[[#This Row],[Predicted Winner]]=NHL2025_26Results[[#This Row],[Winning Team]],"YES","NO")) -> YES | N36: =IF(Table4[[#This Row],[Adjusted Correct]]="-", "",IF(Table4[[#This Row],[Adjusted Correct]]="YES",(Table4[[#This Row],[Strength of Win]]-1)^2,(Table4[[#This Row],[Strength of Win]]-0)^2)) -> 0.2844702 | O36: -0.0087970492 | Q36: Anaheim Ducks | R36: YES
